<?xml version="1.0" encoding="utf-8"?>
<!-- This URDF was automatically created by SolidWorks to URDF Exporter! Originally created by Stephen Brawner (brawner@gmail.com) 
     Commit Version: 1.6.0-4-g7f85cfe  Build Version: 1.6.7995.38578
     For more information, please see http://wiki.ros.org/sw_urdf_exporter -->
<robot
  name="twip.SLDASM">
  <link
    name="base_link">
    <inertial>
      <origin
        xyz="-3.57297979431801E-18 6.70667740944325E-18 0.0859541156140269"
        rpy="0 0 0" />
      <mass
        value="2.58861354857715" />
      <inertia
        ixx="0.00614521723061893"
        ixy="7.22595051285922E-19"
        ixz="3.57380429488389E-19"
        iyy="0.00608229697933838"
        iyz="4.24219841367776E-20"
        izz="0.0026658004868403" />
    </inertial>
    <visual>
      <origin
        xyz="0 0 0"
        rpy="0 0 0" />
      <geometry>
        <mesh
          filename="C:/Users/user/Documents/Doc/simulations/pinnochio/models/twip2/meshes/base_link.STL" />
      </geometry>
      <material
        name="">
        <color
          rgba="0.898039215686275 0.917647058823529 0.929411764705882 1" />
      </material>
    </visual>
    <collision>
      <origin
        xyz="0 0 0"
        rpy="0 0 0" />
      <geometry>
        <mesh
          filename="C:/Users/user/Documents/Doc/simulations/pinnochio/models/twip2/meshes/base_link.STL" />
      </geometry>
    </collision>
  </link>
  <link
    name="wheel-1">
    <inertial>
      <origin
        xyz="0.0072647 3.1225E-17 -2.3939E-16"
        rpy="0 0 0" />
      <mass
        value="0.022531" />
      <inertia
        ixx="5.4481E-06"
        ixy="-3.1759E-22"
        ixz="-1.5411E-22"
        iyy="2.7962E-06"
        iyz="-1.0588E-22"
        izz="2.7962E-06" />
    </inertial>
    <visual>
      <origin
        xyz="0 0 0"
        rpy="0 0 0" />
      <geometry>
        <mesh
          filename="C:/Users/user/Documents/Doc/simulations/pinnochio/models/twip2/meshes/wheel-1.STL" />
      </geometry>
      <material
        name="">
        <color
          rgba="0.89804 0.91765 0.92941 1" />
      </material>
    </visual>
    <collision>
      <origin
        xyz="0 0 0"
        rpy="0 0 0" />
      <geometry>
        <mesh
          filename="C:/Users/user/Documents/Doc/simulations/pinnochio/models/twip2/meshes/wheel-1.STL" />
      </geometry>
    </collision>
  </link>
  <joint
    name="joint-1"
    type="continuous">
    <origin
      xyz="-0.033301 0 0.023"
      rpy="1.7468 0 3.1416" />
    <parent
      link="base_link" />
    <child
      link="wheel-1" />
    <axis
      xyz="1 0 0" />
  </joint>
  <link
    name="wheel-2">
    <inertial>
      <origin
        xyz="-0.073867 0 6.0715E-18"
        rpy="0 0 0" />
      <mass
        value="0.022531" />
      <inertia
        ixx="5.4481E-06"
        ixy="8.7035E-23"
        ixz="-5.1057E-23"
        iyy="2.7962E-06"
        iyz="0"
        izz="2.7962E-06" />
    </inertial>
    <visual>
      <origin
        xyz="0 0 0"
        rpy="0 0 0" />
      <geometry>
        <mesh
          filename="C:/Users/user/Documents/Doc/simulations/pinnochio/models/twip2/meshes/wheel-2.STL" />
      </geometry>
      <material
        name="">
        <color
          rgba="0.89804 0.91765 0.92941 1" />
      </material>
    </visual>
    <collision>
      <origin
        xyz="0 0 0"
        rpy="0 0 0" />
      <geometry>
        <mesh
          filename="C:/Users/user/Documents/Doc/simulations/pinnochio/models/twip2/meshes/wheel-2.STL" />
      </geometry>
    </collision>
  </link>
  <joint
    name="joint-2"
    type="revolute">
    <origin
      xyz="-0.033301 0 0.023"
      rpy="1.7468 0 3.1416" />
    <parent
      link="base_link" />
    <child
      link="wheel-2" />
    <axis
      xyz="-1 0 0" />
    <limit
      lower="0"
      upper="0"
      effort="0"
      velocity="0" />
  </joint>
</robot>