#VRML_SIM R2025a utf8

EXTERNPROTO "https://raw.githubusercontent.com/cyberbotics/webots/R2025a/projects/objects/backgrounds/protos/TexturedBackground.proto"
EXTERNPROTO "https://raw.githubusercontent.com/cyberbotics/webots/R2025a/projects/objects/backgrounds/protos/TexturedBackgroundLight.proto"
EXTERNPROTO "https://raw.githubusercontent.com/cyberbotics/webots/R2025a/projects/objects/floors/protos/RectangleArena.proto"

WorldInfo {
  info [
    "Example use of a Connector device."
  ]
  title "Connector"
}
Viewpoint {
  orientation -0.29018523487892073 0.2996943964820488 0.9088321067037223 1.569655581476285
  position 0.11781750559726312 -0.889246195224159 0.6801123208647919
}
TexturedBackground {
}
TexturedBackgroundLight {
}
RectangleArena {
}
DEF GREEN_BOX Solid {
  translation 0.35 0.05 0.05
  children [
    Shape {
      appearance PBRAppearance {
        baseColor 0 1 0
        roughness 0.2189099510000001
        metalness 0
      }
      geometry DEF BOX0 Box {
        size 0.1 0.23 0.1
      }
    }
  ]
  name "green box"
  boundingObject Shape {
    appearance PBRAppearance {
      roughness 1.1102230246251565e-16
      metalness 0
    }
    geometry USE BOX0
  }
}
DEF BLUE_BOX Solid {
  translation -0.27 -0.2 0.05
  rotation 0 0 1 0.31
  children [
    Shape {
      appearance PBRAppearance {
        baseColor 0 0 1
        roughness 0.519341125
        metalness 0
      }
      geometry DEF BOX1 Box {
        size 0.1 0.1 0.1
      }
    }
  ]
  name "blue box"
  boundingObject Shape {
    appearance PBRAppearance {
      roughness 1.1102230246251565e-16
      metalness 0
    }
    geometry USE BOX1
  }
}
DEF YELLOW_BOX Solid {
  translation -0.15 0.2 0.05
  rotation 0 0 1 0.4
  children [
    Shape {
      appearance PBRAppearance {
        baseColor 1 1 0
        roughness 0.03934117200000009
        metalness 0
      }
      geometry DEF BOX2 Box {
        size 0.3 0.05 0.1
      }
    }
  ]
  name "yellow box"
  boundingObject Shape {
    appearance PBRAppearance {
      roughness 1.1102230246251565e-16
      metalness 0
    }
    geometry USE BOX2
  }
}
DEF PINK_BOX Solid {
  translation 0.35 -0.42 0.05
  children [
    Shape {
      appearance PBRAppearance {
        baseColor 1 0.1 0.3
        roughness 0.16827074099999995
        metalness 0
      }
      geometry DEF BOX3 Box {
        size 0.08 0.15 0.1
      }
    }
  ]
  name "red box"
  boundingObject Shape {
    appearance PBRAppearance {
      roughness 1.1102230246251565e-16
      metalness 0
    }
    geometry USE BOX3
  }
}
DEF LIGHT_MYBOT Robot {
  translation 0.09999989112867264 -0.40400082674100984 -4.384125646587217e-05
  rotation -0.017076464171587227 0.017081863345255768 0.9997082596017953 1.5710873083456467
  children [
    DEF LIGHT_BODY Pose {
      translation 0 0 0.0415
      rotation 0 0 1 1.570796
      children [
        Shape {
          appearance PBRAppearance {
            baseColor 0.117647 0.776471 1
            roughness 0.6980390000000001
            metalness 0
          }
          geometry DEF BODY Cylinder {
            height 0.08
            radius 0.045
          }
        }
      ]
    }
    HingeJoint {
      jointParameters HingeJointParameters {
        position 0.639781704579345
        axis 0 1 0
        anchor 0 0 0.025
      }
      device [
        RotationalMotor {
          name "left wheel motor"
          consumptionFactor 70
        }
        PositionSensor {
          name "left wheel sensor"
          resolution 0.314159
        }
      ]
      endPoint Solid {
        translation 0 0.045000000000000005 0.025
        rotation -0.1797426811285384 0.17974245594375418 -0.9671531513219777 1.6041892401981435
        children [
          DEF WHEEL Pose {
            rotation 0.577656895078166 0.5771968951617173 -0.5771968951617173 -2.093935
            children [
              Shape {
                appearance PBRAppearance {
                  baseColor 1 0 0
                  roughness 1
                  metalness 0
                }
                geometry Cylinder {
                  height 0.01
                  radius 0.025
                }
              }
            ]
          }
        ]
        name "left wheel"
        boundingObject USE WHEEL
        physics DEF PHYSICS_WHEEL Physics {
          density -1
          mass 0.05
        }
        linearVelocity 1.7848563107794004e-07 0.05000575295955544 3.3274370595392504e-06
        angularVelocity -2.000279804841917 1.611488676358043e-05 -2.1030720722568174e-05
      }
    }
    HingeJoint {
      jointParameters HingeJointParameters {
        position 0.6397817027615589
        axis 0 1 0
        anchor 0 0 0.025
      }
      device [
        RotationalMotor {
          name "right wheel motor"
          consumptionFactor 70
        }
        PositionSensor {
          name "right wheel sensor"
          resolution 0.314159
        }
      ]
      endPoint Solid {
        translation 0 -0.045 0.025
        rotation -0.34960967895237033 0.3496096527576403 -0.8692215845694944 1.7104969802598038
        children [
          USE WHEEL
        ]
        name "right wheel"
        boundingObject USE WHEEL
        physics USE PHYSICS_WHEEL
        linearVelocity 1.777965830307765e-07 0.05000294051430702 1.944950424359616e-06
        angularVelocity -2.0002797991454204 1.6066338300640565e-05 -2.1038274572865316e-05
      }
    }
    DEF RIGHT_EYE Pose {
      translation 0.0385 -0.02 0.063
      rotation -0.7268278184260777 -0.4856548786751704 -0.4856548786751704 -1.884582
      children [
        DEF UNUSED_EYE Group {
          children [
            Pose {
              translation 0 0 1e-05
              rotation 0 0 1 0.8
              children [
                Shape {
                  appearance PBRAppearance {
                    baseColor 0.975691 0.981481 0.0252992
                    roughness 1
                    metalness 0
                  }
                  geometry Box {
                    size 0.02 0.005 0.005
                  }
                }
              ]
            }
            Pose {
              rotation 0 0 1 -0.8
              children [
                Shape {
                  appearance PBRAppearance {
                    baseColor 0.975691 0.981481 0.0252992
                    roughness 1
                    metalness 0
                  }
                  geometry Box {
                    size 0.02 0.005 0.005
                  }
                }
              ]
            }
          ]
        }
      ]
    }
    DEF LEFT_EYE Pose {
      translation 0.0385 0.02 0.063
      rotation -0.7268313515069925 0.4856522348690052 0.4856522348690052 -1.884578
      children [
        DEF UNUSED_EYE Group {
          children [
            Pose {
              translation 0 0 -1e-05
              rotation 0 0 1 0.8
              children [
                Shape {
                  appearance PBRAppearance {
                    baseColor 0.975691 0.981481 0.0252992
                    roughness 1
                    metalness 0
                  }
                  geometry Box {
                    size 0.02 0.005 0.005
                  }
                }
              ]
            }
            Pose {
              rotation 0 0 1 -0.8
              children [
                Shape {
                  appearance PBRAppearance {
                    baseColor 0.975691 0.981481 0.0252992
                    roughness 1
                    metalness 0
                  }
                  geometry Box {
                    size 0.02 0.005 0.005
                  }
                }
              ]
            }
          ]
        }
      ]
    }
    DEF SMILE Pose {
      translation 0.036 0 0.025
      rotation 0.25056300542381216 -0.9351130202419243 -0.25056300542381216 1.637834
      children [
        Shape {
          appearance PBRAppearance {
            baseColor 0.721569 0.290196 0.290196
            roughness 1
            metalness 0
          }
          geometry Cylinder {
            height 0.018
            radius 0.009
            subdivision 3
          }
        }
      ]
    }
    DEF HINGE_JOINT_DEVICE HingeJoint {
      jointParameters HingeJointParameters {
        position -1.5699051570459543
        axis 0 -1 0
        anchor 0 0 0.06
      }
      device [
        RotationalMotor {
          name "upper motor"
          maxVelocity 1
          minPosition -1.57
          maxPosition 1.57
        }
        PositionSensor {
          name "upper sensor"
        }
      ]
      endPoint Solid {
        translation 0 0 0.06
        rotation 0 0.9999999999999999 0 1.5699051570459543
        children [
          DEF CONNECTOR_SHAPE Group {
            children [
              Pose {
                translation 0 -0.049 0.025
                children [
                  DEF SIDE_PART Shape {
                    appearance PBRAppearance {
                      baseColor 0.898039 0.898039 0.898039
                      roughness 0.25098
                      metalness 0
                    }
                    geometry Box {
                      size 0.015 0.008 0.05
                    }
                  }
                ]
              }
              Pose {
                translation 0 0.049 0.025
                children [
                  USE SIDE_PART
                ]
              }
              Pose {
                translation 0 0 0.05
                children [
                  Shape {
                    appearance PBRAppearance {
                      baseColor 0.898039 0.898039 0.898039
                      roughness 0.25098
                      metalness 0
                    }
                    geometry Box {
                      size 0.04 0.12 0.01
                    }
                  }
                ]
              }
            ]
          }
          DEF CONNECTOR_DEVICE Connector {
            translation 0 0 0.055
            rotation 0.0003979999369552231 -0.9999998415960378 -0.0003979999369552231 1.570796
            model "magnetic"
            autoLock TRUE
            axisTolerance 3.14
            rotationTolerance 3.14
          }
        ]
        boundingObject USE CONNECTOR_SHAPE
        physics DEF CONNECTOR_SHAPE_PHYSICS Physics {
          density -1
          mass 0.05
        }
        linearVelocity 1.8773342966433943e-06 0.0499863489666561 -7.651245512867283e-05
        angularVelocity -0.0016749406847702266 1.5706612506939877e-05 -3.118066925016546e-05
      }
    }
  ]
  name "MyBot 1"
  boundingObject DEF MYBOT_BOUNDING Pose {
    translation 0 0 0.0415
    rotation 0 0 1 1.570796
    children [
      USE BODY
    ]
  }
  physics DEF MOVING_MYBOT_PHYSICS Physics {
    density -1
    mass 0.05
  }
  controller "connector"
  linearVelocity 1.8837399278851585e-07 0.05000863144392099 2.530549967652006e-06
  angularVelocity -0.00027986690580143937 1.570564457852173e-05 -3.118977487728148e-05
}
DEF HEAVY_MYBOT Robot {
  translation 0.10000000018880732 -0.1500000806736022 -0.00022480350000933513
  rotation 0.015167839490772049 0.015180252727420561 -0.9997697217721258 1.570230255013107
  children [
    DEF MAIN_BODY Pose {
      translation 0 0 0.0415
      rotation 0 0 1 1.570796
      children [
        DEF CONNECTOR_DEVICE Connector {
          translation 0.06 3.98e-05 0.005
          rotation 0.9999998178800441 0.0006035228900864179 -2.3974495633765115e-09 0.000796
          model "magnetic"
          autoLock TRUE
          axisTolerance 3.14
          rotationTolerance 3.14
        }
        Shape {
          appearance PBRAppearance {
            baseColor 0.0820075 0.364731 0.8
            roughness 1
            metalness 0
          }
          geometry USE BODY
        }
      ]
    }
    HingeJoint {
      jointParameters HingeJointParameters {
        position -1.7384580175416886e-07
        axis 0 1 0
        anchor 0 0 0.025
      }
      device [
        RotationalMotor {
          name "left wheel motor"
          consumptionFactor 70
        }
        PositionSensor {
          name "left wheel sensor"
          resolution 0.314159
        }
      ]
      endPoint Solid {
        translation 0 0.045 0.025
        rotation 0.13448703817840912 -0.13448703817834642 -0.9817466440604801 1.5892180233799997
        children [
          DEF WHEEL Pose {
            rotation 0.577656895078166 0.5771968951617173 -0.5771968951617173 -2.093935
            children [
              Shape {
                appearance PBRAppearance {
                  baseColor 1 0 0
                  roughness 1
                  metalness 0
                }
                geometry Cylinder {
                  height 0.01
                  radius 0.025
                }
              }
            ]
          }
        ]
        name "left wheel"
        boundingObject USE WHEEL
        physics DEF PHYSICS_WHEEL Physics {
          density -1
          mass 0.05
        }
        linearVelocity -2.707257657084406e-10 4.3608852186516434e-07 2.857111823585049e-08
        angularVelocity -1.7438351915398343e-05 -1.3660414320751382e-08 4.188331075924667e-11
      }
    }
    HingeJoint {
      jointParameters HingeJointParameters {
        position -1.7384382200447135e-07
        axis 0 1 0
        anchor 0 0 0.025
      }
      device [
        RotationalMotor {
          name "right wheel motor"
          consumptionFactor 70
        }
        PositionSensor {
          name "right wheel sensor"
          resolution 0.314159
        }
      ]
      endPoint Solid {
        translation 0 -0.045 0.025
        rotation -0.06235691469767654 0.06235691469768426 -0.9961040258822231 1.5746999891596283
        children [
          USE WHEEL
        ]
        name "right wheel"
        boundingObject USE WHEEL
        physics USE PHYSICS_WHEEL
        linearVelocity -4.0974752816962313e-10 4.3608508403498293e-07 2.8589073224344427e-08
        angularVelocity -1.7438352298580324e-05 -1.3708246177728458e-08 -2.4904054183798925e-10
      }
    }
    USE LEFT_EYE
    USE RIGHT_EYE
    USE SMILE
    DEF HINGE_JOINT_DEVICE HingeJoint {
      jointParameters HingeJointParameters {
        position -1.5699051709224188
        axis 0 -1 0
        anchor 0 0 0.06
      }
      device [
        RotationalMotor {
          name "upper motor"
          maxVelocity 1
          minPosition -1.57
          maxPosition 1.57
        }
        PositionSensor {
          name "upper sensor"
        }
      ]
      endPoint Solid {
        translation 0 0 0.06
        rotation -3.9819590510892966e-14 1 1.341959960902884e-13 1.569905170922419
        children [
          DEF CONNECTOR_SHAPE Group {
            children [
              Pose {
                translation 0 -0.049 0.025
                children [
                  DEF SIDE_PART Shape {
                    appearance PBRAppearance {
                      baseColor 0.898039 0.898039 0.898039
                      roughness 0.25098
                      metalness 0
                    }
                    geometry Box {
                      size 0.015 0.008 0.05
                    }
                  }
                ]
              }
              Pose {
                translation 0 0.049 0.025
                children [
                  USE SIDE_PART
                ]
              }
              Pose {
                translation 0 0 0.05
                children [
                  Shape {
                    appearance PBRAppearance {
                      baseColor 0.898039 0.898039 0.898039
                      roughness 0.25098
                      metalness 0
                    }
                    geometry Box {
                      size 0.04 0.12 0.01
                    }
                  }
                ]
              }
            ]
          }
        ]
        boundingObject USE CONNECTOR_SHAPE
        physics DEF CONNECTOR_SHAPE_PHYSICS Physics {
          density -1
          mass 0.05
        }
        linearVelocity -2.2189824097539377e-08 2.7840550207224265e-05 -6.554503841304488e-05
        angularVelocity 0.001377430960982281 1.09716481980552e-06 -5.637504407469265e-10
      }
    }
  ]
  name "MyBot 2"
  boundingObject USE MYBOT_BOUNDING
  physics DEF STATIC_MYBOT_PHYSICS Physics {
    density -1
    mass 0.5
  }
  controller "connector"
  linearVelocity -5.687470276347366e-10 7.205110914652135e-07 3.710799688860789e-08
  angularVelocity -1.743834575062232e-05 -1.3684259197438597e-08 -1.038124543564911e-10
}
DEF HEAVY_MYBOT Robot {
  translation 0.23028000018887462 -0.14989608075543973 -0.00022480380992832144
  rotation 0.015167817778630681 0.01518023099906174 -0.9997697224314454 1.570230254353779
  children [
    DEF MAIN_BODY Pose {
      translation 0 0 0.0415
      rotation 0 0 1 1.570796
      children [
        DEF CONNECTOR_DEVICE Connector {
          translation -0.06 3.98e-05 0.00499982
          rotation 2.8625497732803424e-12 0.9999999207980096 0.00039799996847760785 3.14159
          model "magnetic"
          autoLock TRUE
          axisTolerance 3.14
          rotationTolerance 3.14
        }
        Shape {
          appearance PBRAppearance {
            baseColor 0.0820075 0.364731 0.8
            roughness 1
            metalness 0
          }
          geometry USE BODY
        }
      ]
    }
    HingeJoint {
      jointParameters HingeJointParameters {
        position -1.7384598116620964e-07
        axis 0 1 0
        anchor 0 0 0.025
      }
      device [
        RotationalMotor {
          name "left wheel motor"
          consumptionFactor 70
        }
        PositionSensor {
          name "left wheel sensor"
          resolution 0.314159
        }
      ]
      endPoint Solid {
        translation 0 0.044999999999999984 0.025
        rotation 0.1344870381784956 -0.1344870381784329 -0.9817466440604564 1.5892180233800244
        children [
          DEF WHEEL Pose {
            rotation 0.577656895078166 0.5771968951617173 -0.5771968951617173 -2.093935
            children [
              Shape {
                appearance PBRAppearance {
                  baseColor 1 0 0
                  roughness 1
                  metalness 0
                }
                geometry Cylinder {
                  height 0.01
                  radius 0.025
                }
              }
            ]
          }
        ]
        name "left wheel"
        boundingObject USE WHEEL
        physics DEF PHYSICS_WHEEL Physics {
          density -1
          mass 0.05
        }
        linearVelocity -2.785355055393867e-10 4.458269997148918e-07 2.4442370971612588e-08
        angularVelocity -1.7828069216851295e-05 -1.3977538387539702e-08 3.761827424029017e-11
      }
    }
    HingeJoint {
      jointParameters HingeJointParameters {
        position -1.738440094101179e-07
        axis 0 1 0
        anchor 0 0 0.025
      }
      device [
        RotationalMotor {
          name "right wheel motor"
          consumptionFactor 70
        }
        PositionSensor {
          name "right wheel sensor"
          resolution 0.314159
        }
      ]
      endPoint Solid {
        translation 0 -0.044999999999999984 0.025
        rotation -0.06235691469758355 0.062356914697591276 -0.9961040258822347 1.5746999891596163
        children [
          USE WHEEL
        ]
        name "right wheel"
        boundingObject USE WHEEL
        physics USE PHYSICS_WHEEL
        linearVelocity -4.176103644641507e-10 4.4582358120614307e-07 2.4460051121954045e-08
        angularVelocity -1.7828069606767147e-05 -1.4017968285579562e-08 -2.4352109788989994e-10
      }
    }
    USE LEFT_EYE
    USE RIGHT_EYE
    USE SMILE
    DEF HINGE_JOINT_DEVICE HingeJoint {
      jointParameters HingeJointParameters {
        position -1.5699051709222598
        axis 0 -1 0
        anchor 0 0 0.06
      }
      device [
        RotationalMotor {
          name "upper motor"
          maxVelocity 1
          minPosition -1.57
          maxPosition 1.57
        }
        PositionSensor {
          name "upper sensor"
        }
      ]
      endPoint Solid {
        translation 0 0 0.06
        rotation -3.903419424835382e-14 1 1.336449915248593e-13 1.5699051709222596
        children [
          DEF CONNECTOR_SHAPE Group {
            children [
              Pose {
                translation 0 -0.049 0.025
                children [
                  DEF SIDE_PART Shape {
                    appearance PBRAppearance {
                      baseColor 0.898039 0.898039 0.898039
                      roughness 0.25098
                      metalness 0
                    }
                    geometry Box {
                      size 0.015 0.008 0.05
                    }
                  }
                ]
              }
              Pose {
                translation 0 0.049 0.025
                children [
                  USE SIDE_PART
                ]
              }
              Pose {
                translation 0 0 0.05
                children [
                  Shape {
                    appearance PBRAppearance {
                      baseColor 0.898039 0.898039 0.898039
                      roughness 0.25098
                      metalness 0
                    }
                    geometry Box {
                      size 0.04 0.12 0.01
                    }
                  }
                ]
              }
            ]
          }
        ]
        boundingObject USE CONNECTOR_SHAPE
        physics DEF CONNECTOR_SHAPE_PHYSICS Physics {
          density -1
          mass 0.05
        }
        linearVelocity -2.2208375414211324e-08 2.786363888668939e-05 -6.553130761977218e-05
        angularVelocity 0.0013770412458289063 1.0968514869253914e-06 -5.631254341874557e-10
      }
    }
  ]
  name "MyBot 3"
  boundingObject USE MYBOT_BOUNDING
  physics USE STATIC_MYBOT_PHYSICS
  controller "connector"
  linearVelocity -5.818450056364049e-10 7.367797689199347e-07 3.3091296245623286e-08
  angularVelocity -1.7828063276466372e-05 -1.399759229378472e-08 -1.0319146126630217e-10
}
