<?xml version="1.0"?>
<robot name="body__32__">
    <link name="body__32__">
        <inertial>
            <origin rpy="-3.141593 3.141593 -3.141593" xyz="0.000000 0.000000 0.000000" />
            <inertia ixy="0.0" ixx="0.24166665971279" ixz="0.0" izz="0.04166666790843" iyz="0.0" iyy="0.21666666865349" />
            <mass value="2.0" />
        </inertial>
        <visual>
      <origin
        xyz="0 0 0"
        rpy="0 0 0" />
      <geometry>
        <mesh
          filename="C:/Users/user/Documents/Doc/simulations/pinnochio/models/twip/meshes/base_link.STL" />
      </geometry>
      <material
        name="">
        <color
          rgba="0.898039215686275 0.917647058823529 0.929411764705882 1" />
      </material>
    </visual>
        <collision>
            <origin rpy="-3.141593 3.141593 -3.141593" xyz="0.000000 0.000000 0.000000" />
            <geometry>
                <box size="0.100000 0.200000 0.500000" />
            </geometry>
        </collision>
    </link>
    <link name="Wheel1__34__">
        <inertial>
            <origin rpy="-3.141593 3.141593 -3.141593" xyz="0.000000 -0.000000 0.000000" />
            <inertia ixy="0.0" ixx="0.00060672010295093" ixz="0.0" izz="0.0011780972126871" iyz="0.0" iyy="0.00060672010295093" />
            <mass value="0.23561945557594" />
        </inertial>
        <visual>
      <origin
        xyz="0 0 0"
        rpy="0 0 0" />
      <geometry>
        <mesh
          filename="C:/Users/user/Documents/Doc/simulations/pinnochio/models/twip/meshes/wheel-1.STL" />
      </geometry>
      <material
        name="">
        <color
          rgba="0.89804 0.91765 0.92941 1" />
      </material>
    </visual>
        <collision>
            <origin rpy="-3.141593 3.141593 -3.141593" xyz="0.000000 0.000000 0.000000" />
            <geometry>
                <cylinder length="0.029999999329448" radius="0.10000000149012" />
            </geometry>
        </collision>
    </link>
    <joint name="Revolute_joint1__33__" type="continuous">
        <axis xyz="0 0 1" />
        <parent link="body__32__" />
        <child link="Wheel1__34__" />
        <origin rpy="-1.570770 3.141593 -3.141593" xyz="0.000000 -0.180000 -0.250000" />
        <limit effort="100000000.0" velocity="100"/>
        <dynamics damping="0.001" friction="0.0025"/>
    </joint>
    <link name="Wheel2__36__">
        <inertial>
            <origin rpy="-3.141593 3.141593 -3.141593" xyz="0.000000 -0.000000 0.000000" />
            <inertia ixy="0.0" ixx="0.00060672010295093" ixz="0.0" izz="0.0011780972126871" iyz="0.0" iyy="0.00060672010295093" />
            <mass value="0.23561945557594" />
        </inertial>
        <visual>
      <origin
        xyz="0 0 0"
        rpy="0 0 0" />
      <geometry>
        <mesh
          filename="C:/Users/user/Documents/Doc/simulations/pinnochio/models/twip/meshes/wheel-1.STL" />
      </geometry>
      <material
        name="">
        <color
          rgba="0.89804 0.91765 0.92941 1" />
      </material>
    </visual>
        <collision>
            <origin rpy="-3.141593 3.141593 -3.141593" xyz="0.000000 0.000000 0.000000" />
            <geometry>
                <cylinder length="0.029999999329448" radius="0.10000001639128" />
            </geometry>
        </collision>
    </link>
    <joint name="Revolute_joint2__35__" type="continuous">
        <axis xyz="0 0 1" />
        <parent link="body__32__" />
        <child link="Wheel2__36__" />
        <origin rpy="-1.570771 3.141593 3.141593" xyz="0.000000 0.180000 -0.250000" />
        <limit effort="100000000.0" velocity="100"/>
        <dynamics damping="0.001" friction="0.0025"/>
    </joint>
</robot>